#VRML_SIM R2023b utf8

EXTERNPROTO "https://raw.githubusercontent.com/cyberbotics/webots/R2023b/projects/appearances/protos/OsbWood.proto"
EXTERNPROTO "https://raw.githubusercontent.com/cyberbotics/webots/R2023b/projects/objects/floors/protos/RectangleArena.proto"
EXTERNPROTO "https://raw.githubusercontent.com/cyberbotics/webots/R2023b/projects/objects/backgrounds/protos/TexturedBackground.proto"
EXTERNPROTO "https://raw.githubusercontent.com/cyberbotics/webots/R2023b/projects/objects/backgrounds/protos/TexturedBackgroundLight.proto"

WorldInfo {
  info [
    "In this example, the robot turns on a slope."
    "Its accelerometer sensor is used to switch on the bottommost LED."
  ]
  title "Accelerometer"
  basicTimeStep 8
  contactProperties [
    ContactProperties {
      material2 "body"
      coulombFriction [
        0
      ]
      softCFM 0.1
    }
  ]
}
Viewpoint {
  orientation 0.11304047320713873 0.08769079064658707 -0.9897131789831247 1.5407362460169924
  position 0.15175917406919953 1.4384890100923173 0.40868911180881806
}
TexturedBackground {
}
TexturedBackgroundLight {
}
RectangleArena {
}
PointLight {
  attenuation 0 0 1
  intensity 0.6
  location 0.6 0 0
}
DEF SLOPE Solid {
  translation 0 0 0.15
  rotation 1 6.35719e-09 -9.58979e-09 -1.9707953071795865
  children [
    Shape {
      appearance OsbWood {
        textureTransform TextureTransform {
          scale 0.5 2
        }
      }
      geometry DEF BOX0 Box {
        size 0.2 0.02 0.8
      }
    }
  ]
  name "green box"
  boundingObject USE BOX0
}
Robot {
  translation -0.0129105 0.00574839 0.16008
  rotation -0.9699756844182246 0.0682742777869506 -0.23342192405613213 0.460805
  children [
    DEF SMILE Pose {
      translation 0 0.04 0.03
      rotation 0.5773509358560258 0.577349935856137 0.577349935856137 -2.094395307179586
      children [
        Shape {
          appearance PBRAppearance {
            baseColor 1 0 0
            roughness 1
            metalness 0
          }
          geometry Cylinder {
            height 0.01
            radius 0.01
          }
        }
      ]
    }
    DistanceSensor {
      children [
        Pose {
          translation -0.02 0.04 0.06
          rotation 0.9983989399121678 0 0.05656462483089129 -1.3089953071795861
          children [
            Shape {
              appearance PBRAppearance {
                baseColor 1 1 0
                roughness 1
                metalness 0
              }
              geometry Cylinder {
                height 0.01
                radius 0.01
              }
            }
          ]
        }
      ]
      name "ds2"
    }
    DistanceSensor {
      children [
        Pose {
          translation 0.02 0.03 0.06
          rotation 0.5773489358556708 -0.5773509358554485 0.5773509358554485 2.0944
          children [
            Shape {
              appearance PBRAppearance {
                baseColor 1 1 0
                roughness 1
                metalness 0
              }
              geometry Cylinder {
                height 0.03
                radius 0.01
              }
            }
          ]
        }
      ]
      name "ds1"
    }
    HingeJoint {
      endPoint Solid {
        translation 0 0 0.01
        rotation -0.692412079370855 0.20280102324698124 -0.6924140793710842 2.46599
        children [
          Pose {
          }
          Shape {
            appearance PBRAppearance {
              baseColor 1 0 0
              roughness 1
              metalness 0
            }
            geometry Cylinder {
              height 0.1
              radius 0.02
            }
          }
        ]
      }
    }
    Accelerometer {
    }
    Pose {
      translation 0 0 0.0415
      children [
        Shape {
          appearance PBRAppearance {
            baseColor 0.0820075 0.364731 0.8
            roughness 1
            metalness 0
          }
          geometry DEF BODY Cylinder {
            height 0.08
            radius 0.045
          }
        }
      ]
    }
  ]
  name "MyBot"
  contactMaterial "body"
  boundingObject Pose {
    translation 0 0 0.0415
    rotation 0 0 1 -1.570796
    children [
      USE BODY
    ]
  }
  physics Physics {
    density -1
    mass 0.5
  }
  controller "accelerometer"
}
